// Folgender Code wirft einen ReferenceError

try {
  meineLieblingsFunktion();
} catch (error) {
  console.error("ReferenceError behandelt:", error.message);
} finally {
  console.log(
    "Die Ausf√ºhrung vom Code wurde versucht, aber ist mit einem Fehler!"
  );
}
